[2024-11-21T03:46:01.656+0000] {local_task_job_runner.py:123} INFO - ::group::Pre task execution logs
[2024-11-21T03:46:01.671+0000] {taskinstance.py:2613} INFO - Dependencies all met for dep_context=non-requeueable deps ti=<TaskInstance: weather_stock_prediction.fetch_data manual__2024-11-21T03:45:59.410574+00:00 [queued]>
[2024-11-21T03:46:01.680+0000] {taskinstance.py:2613} INFO - Dependencies all met for dep_context=requeueable deps ti=<TaskInstance: weather_stock_prediction.fetch_data manual__2024-11-21T03:45:59.410574+00:00 [queued]>
[2024-11-21T03:46:01.682+0000] {taskinstance.py:2866} INFO - Starting attempt 1 of 2
[2024-11-21T03:46:01.692+0000] {taskinstance.py:2889} INFO - Executing <Task(PythonOperator): fetch_data> on 2024-11-21 03:45:59.410574+00:00
[2024-11-21T03:46:01.700+0000] {warnings.py:112} WARNING - /home/***/.local/lib/python3.12/site-packages/***/task/task_runner/standard_task_runner.py:70: DeprecationWarning: This process (pid=782) is multi-threaded, use of fork() may lead to deadlocks in the child.
  pid = os.fork()

[2024-11-21T03:46:01.702+0000] {standard_task_runner.py:72} INFO - Started process 855 to run task
[2024-11-21T03:46:01.703+0000] {standard_task_runner.py:104} INFO - Running: ['***', 'tasks', 'run', 'weather_stock_prediction', 'fetch_data', 'manual__2024-11-21T03:45:59.410574+00:00', '--job-id', '174', '--raw', '--subdir', 'DAGS_FOLDER/dag.py', '--cfg-path', '/tmp/tmpty2ev7ey']
[2024-11-21T03:46:01.706+0000] {standard_task_runner.py:105} INFO - Job 174: Subtask fetch_data
[2024-11-21T03:46:01.754+0000] {task_command.py:467} INFO - Running <TaskInstance: weather_stock_prediction.fetch_data manual__2024-11-21T03:45:59.410574+00:00 [running]> on host cba1e82f0ade
[2024-11-21T03:46:01.813+0000] {taskinstance.py:3132} INFO - Exporting env vars: AIRFLOW_CTX_DAG_OWNER='***' AIRFLOW_CTX_DAG_ID='weather_stock_prediction' AIRFLOW_CTX_TASK_ID='fetch_data' AIRFLOW_CTX_EXECUTION_DATE='2024-11-21T03:45:59.410574+00:00' AIRFLOW_CTX_TRY_NUMBER='1' AIRFLOW_CTX_DAG_RUN_ID='manual__2024-11-21T03:45:59.410574+00:00'
[2024-11-21T03:46:01.816+0000] {logging_mixin.py:190} INFO - Task instance is in running state
[2024-11-21T03:46:01.816+0000] {logging_mixin.py:190} INFO -  Previous state of the Task instance: queued
[2024-11-21T03:46:01.816+0000] {logging_mixin.py:190} INFO - Current task name:fetch_data state:running start_date:2024-11-21 03:46:01.673980+00:00
[2024-11-21T03:46:01.816+0000] {logging_mixin.py:190} INFO - Dag name:weather_stock_prediction and current dag run status:running
[2024-11-21T03:46:01.817+0000] {taskinstance.py:731} INFO - ::endgroup::
[2024-11-21T03:46:01.819+0000] {taskinstance.py:3311} ERROR - Task failed with exception
Traceback (most recent call last):
  File "/home/airflow/.local/lib/python3.12/site-packages/airflow/models/taskinstance.py", line 767, in _execute_task
    result = _execute_callable(context=context, **execute_callable_kwargs)
             ^^^^^^^^^^^^^^^^^^^^^^^^^^^^^^^^^^^^^^^^^^^^^^^^^^^^^^^^^^^^^
  File "/home/airflow/.local/lib/python3.12/site-packages/airflow/models/taskinstance.py", line 733, in _execute_callable
    return ExecutionCallableRunner(
           ^^^^^^^^^^^^^^^^^^^^^^^^
  File "/home/airflow/.local/lib/python3.12/site-packages/airflow/utils/operator_helpers.py", line 252, in run
    return self.func(*args, **kwargs)
           ^^^^^^^^^^^^^^^^^^^^^^^^^^
  File "/home/airflow/.local/lib/python3.12/site-packages/airflow/models/baseoperator.py", line 417, in wrapper
    return func(self, *args, **kwargs)
           ^^^^^^^^^^^^^^^^^^^^^^^^^^^
  File "/home/airflow/.local/lib/python3.12/site-packages/airflow/operators/python.py", line 238, in execute
    return_value = self.execute_callable()
                   ^^^^^^^^^^^^^^^^^^^^^^^
  File "/home/airflow/.local/lib/python3.12/site-packages/airflow/operators/python.py", line 256, in execute_callable
    return runner.run(*self.op_args, **self.op_kwargs)
           ^^^^^^^^^^^^^^^^^^^^^^^^^^^^^^^^^^^^^^^^^^^
  File "/home/airflow/.local/lib/python3.12/site-packages/airflow/utils/operator_helpers.py", line 252, in run
    return self.func(*args, **kwargs)
           ^^^^^^^^^^^^^^^^^^^^^^^^^^
  File "/opt/airflow/dags/dag.py", line 28, in fetch_data
    data["date"] = data["DOY"].apply(lambda doy: (base_date + datetime.timedelta(days=doy - 1)).strftime('%Y-%m-%d'))
                   ^^^^
UnboundLocalError: cannot access local variable 'data' where it is not associated with a value
[2024-11-21T03:46:01.828+0000] {logging_mixin.py:190} INFO - Task instance in failure state
[2024-11-21T03:46:01.829+0000] {logging_mixin.py:190} INFO - Task start:2024-11-21 03:46:01.673980+00:00 end:2024-11-21 03:46:01.827823+00:00 duration:0.153843
[2024-11-21T03:46:01.829+0000] {logging_mixin.py:190} INFO - Task:<Task(PythonOperator): fetch_data> dag:<DAG: weather_stock_prediction> dagrun:<DagRun weather_stock_prediction @ 2024-11-21 03:45:59.410574+00:00: manual__2024-11-21T03:45:59.410574+00:00, state:running, queued_at: 2024-11-21 03:45:59.419264+00:00. externally triggered: True>
[2024-11-21T03:46:01.829+0000] {logging_mixin.py:190} INFO - Failure caused by cannot access local variable 'data' where it is not associated with a value
[2024-11-21T03:46:01.829+0000] {taskinstance.py:1225} INFO - Marking task as UP_FOR_RETRY. dag_id=weather_stock_prediction, task_id=fetch_data, run_id=manual__2024-11-21T03:45:59.410574+00:00, execution_date=20241121T034559, start_date=20241121T034601, end_date=20241121T034601
[2024-11-21T03:46:01.838+0000] {taskinstance.py:340} INFO - ::group::Post task execution logs
[2024-11-21T03:46:01.840+0000] {standard_task_runner.py:124} ERROR - Failed to execute job 174 for task fetch_data (cannot access local variable 'data' where it is not associated with a value; 855)
Traceback (most recent call last):
  File "/home/airflow/.local/lib/python3.12/site-packages/airflow/task/task_runner/standard_task_runner.py", line 117, in _start_by_fork
    ret = args.func(args, dag=self.dag)
          ^^^^^^^^^^^^^^^^^^^^^^^^^^^^^
  File "/home/airflow/.local/lib/python3.12/site-packages/airflow/cli/cli_config.py", line 49, in command
    return func(*args, **kwargs)
           ^^^^^^^^^^^^^^^^^^^^^
  File "/home/airflow/.local/lib/python3.12/site-packages/airflow/utils/cli.py", line 116, in wrapper
    return f(*args, **kwargs)
           ^^^^^^^^^^^^^^^^^^
  File "/home/airflow/.local/lib/python3.12/site-packages/airflow/cli/commands/task_command.py", line 483, in task_run
    task_return_code = _run_task_by_selected_method(args, _dag, ti)
                       ^^^^^^^^^^^^^^^^^^^^^^^^^^^^^^^^^^^^^^^^^^^^
  File "/home/airflow/.local/lib/python3.12/site-packages/airflow/cli/commands/task_command.py", line 256, in _run_task_by_selected_method
    return _run_raw_task(args, ti)
           ^^^^^^^^^^^^^^^^^^^^^^^
  File "/home/airflow/.local/lib/python3.12/site-packages/airflow/cli/commands/task_command.py", line 341, in _run_raw_task
    return ti._run_raw_task(
           ^^^^^^^^^^^^^^^^^
  File "/home/airflow/.local/lib/python3.12/site-packages/airflow/utils/session.py", line 97, in wrapper
    return func(*args, session=session, **kwargs)
           ^^^^^^^^^^^^^^^^^^^^^^^^^^^^^^^^^^^^^^
  File "/home/airflow/.local/lib/python3.12/site-packages/airflow/models/taskinstance.py", line 3005, in _run_raw_task
    return _run_raw_task(
           ^^^^^^^^^^^^^^
  File "/home/airflow/.local/lib/python3.12/site-packages/airflow/models/taskinstance.py", line 273, in _run_raw_task
    TaskInstance._execute_task_with_callbacks(
  File "/home/airflow/.local/lib/python3.12/site-packages/airflow/models/taskinstance.py", line 3159, in _execute_task_with_callbacks
    result = self._execute_task(context, task_orig)
             ^^^^^^^^^^^^^^^^^^^^^^^^^^^^^^^^^^^^^^
  File "/home/airflow/.local/lib/python3.12/site-packages/airflow/models/taskinstance.py", line 3183, in _execute_task
    return _execute_task(self, context, task_orig)
           ^^^^^^^^^^^^^^^^^^^^^^^^^^^^^^^^^^^^^^^
  File "/home/airflow/.local/lib/python3.12/site-packages/airflow/models/taskinstance.py", line 767, in _execute_task
    result = _execute_callable(context=context, **execute_callable_kwargs)
             ^^^^^^^^^^^^^^^^^^^^^^^^^^^^^^^^^^^^^^^^^^^^^^^^^^^^^^^^^^^^^
  File "/home/airflow/.local/lib/python3.12/site-packages/airflow/models/taskinstance.py", line 733, in _execute_callable
    return ExecutionCallableRunner(
           ^^^^^^^^^^^^^^^^^^^^^^^^
  File "/home/airflow/.local/lib/python3.12/site-packages/airflow/utils/operator_helpers.py", line 252, in run
    return self.func(*args, **kwargs)
           ^^^^^^^^^^^^^^^^^^^^^^^^^^
  File "/home/airflow/.local/lib/python3.12/site-packages/airflow/models/baseoperator.py", line 417, in wrapper
    return func(self, *args, **kwargs)
           ^^^^^^^^^^^^^^^^^^^^^^^^^^^
  File "/home/airflow/.local/lib/python3.12/site-packages/airflow/operators/python.py", line 238, in execute
    return_value = self.execute_callable()
                   ^^^^^^^^^^^^^^^^^^^^^^^
  File "/home/airflow/.local/lib/python3.12/site-packages/airflow/operators/python.py", line 256, in execute_callable
    return runner.run(*self.op_args, **self.op_kwargs)
           ^^^^^^^^^^^^^^^^^^^^^^^^^^^^^^^^^^^^^^^^^^^
  File "/home/airflow/.local/lib/python3.12/site-packages/airflow/utils/operator_helpers.py", line 252, in run
    return self.func(*args, **kwargs)
           ^^^^^^^^^^^^^^^^^^^^^^^^^^
  File "/opt/airflow/dags/dag.py", line 28, in fetch_data
    data["date"] = data["DOY"].apply(lambda doy: (base_date + datetime.timedelta(days=doy - 1)).strftime('%Y-%m-%d'))
                   ^^^^
UnboundLocalError: cannot access local variable 'data' where it is not associated with a value
[2024-11-21T03:46:01.886+0000] {local_task_job_runner.py:266} INFO - Task exited with return code 1
[2024-11-21T03:46:01.901+0000] {taskinstance.py:3895} INFO - 0 downstream tasks scheduled from follow-on schedule check
[2024-11-21T03:46:01.902+0000] {local_task_job_runner.py:245} INFO - ::endgroup::
