[2024-11-21T02:09:33.560+0000] {local_task_job_runner.py:123} INFO - ::group::Pre task execution logs
[2024-11-21T02:09:33.575+0000] {taskinstance.py:2613} INFO - Dependencies all met for dep_context=non-requeueable deps ti=<TaskInstance: weather_stock_prediction.create_prediction_table manual__2024-11-21T02:09:25.236263+00:00 [queued]>
[2024-11-21T02:09:33.585+0000] {taskinstance.py:2613} INFO - Dependencies all met for dep_context=requeueable deps ti=<TaskInstance: weather_stock_prediction.create_prediction_table manual__2024-11-21T02:09:25.236263+00:00 [queued]>
[2024-11-21T02:09:33.586+0000] {taskinstance.py:2866} INFO - Starting attempt 1 of 2
[2024-11-21T02:09:33.603+0000] {taskinstance.py:2889} INFO - Executing <Task(PostgresOperator): create_prediction_table> on 2024-11-21 02:09:25.236263+00:00
[2024-11-21T02:09:33.613+0000] {warnings.py:112} WARNING - /home/***/.local/lib/python3.12/site-packages/***/task/task_runner/standard_task_runner.py:70: DeprecationWarning: This process (pid=1475) is multi-threaded, use of fork() may lead to deadlocks in the child.
  pid = os.fork()

[2024-11-21T02:09:33.615+0000] {standard_task_runner.py:72} INFO - Started process 1616 to run task
[2024-11-21T02:09:33.629+0000] {standard_task_runner.py:104} INFO - Running: ['***', 'tasks', 'run', 'weather_stock_prediction', 'create_prediction_table', 'manual__2024-11-21T02:09:25.236263+00:00', '--job-id', '49', '--raw', '--subdir', 'DAGS_FOLDER/dag.py', '--cfg-path', '/tmp/tmpe07vpcbr']
[2024-11-21T02:09:33.632+0000] {standard_task_runner.py:105} INFO - Job 49: Subtask create_prediction_table
[2024-11-21T02:09:34.042+0000] {task_command.py:467} INFO - Running <TaskInstance: weather_stock_prediction.create_prediction_table manual__2024-11-21T02:09:25.236263+00:00 [running]> on host 914c68583a3e
[2024-11-21T02:09:34.306+0000] {taskinstance.py:3132} INFO - Exporting env vars: AIRFLOW_CTX_DAG_OWNER='***' AIRFLOW_CTX_DAG_ID='weather_stock_prediction' AIRFLOW_CTX_TASK_ID='create_prediction_table' AIRFLOW_CTX_EXECUTION_DATE='2024-11-21T02:09:25.236263+00:00' AIRFLOW_CTX_TRY_NUMBER='1' AIRFLOW_CTX_DAG_RUN_ID='manual__2024-11-21T02:09:25.236263+00:00'
[2024-11-21T02:09:34.311+0000] {logging_mixin.py:190} INFO - Task instance is in running state
[2024-11-21T02:09:34.312+0000] {logging_mixin.py:190} INFO -  Previous state of the Task instance: queued
[2024-11-21T02:09:34.318+0000] {logging_mixin.py:190} INFO - Current task name:create_prediction_table state:running start_date:2024-11-21 02:09:33.576135+00:00
[2024-11-21T02:09:34.322+0000] {logging_mixin.py:190} INFO - Dag name:weather_stock_prediction and current dag run status:running
[2024-11-21T02:09:34.324+0000] {taskinstance.py:731} INFO - ::endgroup::
[2024-11-21T02:09:34.325+0000] {sql.py:278} INFO - Executing: 
    CREATE TABLE IF NOT EXISTS predictions (
        date DATETIME
        temperature FLOAT, 
        min_temperature FLOAT,
        max_temperature FLOAT,
        humidity FLOAT,
        wind_speed FLOAT,
        price FLOAT
    );
    
[2024-11-21T02:09:34.348+0000] {base.py:84} INFO - Retrieving connection 'asdf'
[2024-11-21T02:09:34.363+0000] {base.py:84} INFO - Retrieving connection 'asdf'
[2024-11-21T02:09:34.374+0000] {sql.py:544} INFO - Running statement: 
    CREATE TABLE IF NOT EXISTS predictions (
        date DATETIME
        temperature FLOAT, 
        min_temperature FLOAT,
        max_temperature FLOAT,
        humidity FLOAT,
        wind_speed FLOAT,
        price FLOAT
    );
    , parameters: None
[2024-11-21T02:09:34.380+0000] {taskinstance.py:3311} ERROR - Task failed with exception
Traceback (most recent call last):
  File "/home/airflow/.local/lib/python3.12/site-packages/airflow/models/taskinstance.py", line 767, in _execute_task
    result = _execute_callable(context=context, **execute_callable_kwargs)
             ^^^^^^^^^^^^^^^^^^^^^^^^^^^^^^^^^^^^^^^^^^^^^^^^^^^^^^^^^^^^^
  File "/home/airflow/.local/lib/python3.12/site-packages/airflow/models/taskinstance.py", line 733, in _execute_callable
    return ExecutionCallableRunner(
           ^^^^^^^^^^^^^^^^^^^^^^^^
  File "/home/airflow/.local/lib/python3.12/site-packages/airflow/utils/operator_helpers.py", line 252, in run
    return self.func(*args, **kwargs)
           ^^^^^^^^^^^^^^^^^^^^^^^^^^
  File "/home/airflow/.local/lib/python3.12/site-packages/airflow/models/baseoperator.py", line 417, in wrapper
    return func(self, *args, **kwargs)
           ^^^^^^^^^^^^^^^^^^^^^^^^^^^
  File "/home/airflow/.local/lib/python3.12/site-packages/airflow/providers/common/sql/operators/sql.py", line 284, in execute
    output = hook.run(
             ^^^^^^^^^
  File "/home/airflow/.local/lib/python3.12/site-packages/airflow/providers/common/sql/hooks/sql.py", line 489, in run
    self._run_command(cur, sql_statement, parameters)
  File "/home/airflow/.local/lib/python3.12/site-packages/airflow/providers/common/sql/hooks/sql.py", line 549, in _run_command
    cur.execute(sql_statement)
psycopg2.errors.SyntaxError: syntax error at or near "temperature"
LINE 4:         temperature FLOAT, 
                ^

[2024-11-21T02:09:34.425+0000] {logging_mixin.py:190} INFO - Task instance in failure state
[2024-11-21T02:09:34.428+0000] {logging_mixin.py:190} INFO - Task start:2024-11-21 02:09:33.576135+00:00 end:2024-11-21 02:09:34.423664+00:00 duration:0.847529
[2024-11-21T02:09:34.429+0000] {logging_mixin.py:190} INFO - Task:<Task(PostgresOperator): create_prediction_table> dag:<DAG: weather_stock_prediction> dagrun:<DagRun weather_stock_prediction @ 2024-11-21 02:09:25.236263+00:00: manual__2024-11-21T02:09:25.236263+00:00, state:running, queued_at: 2024-11-21 02:09:25.264819+00:00. externally triggered: True>
[2024-11-21T02:09:34.431+0000] {logging_mixin.py:190} INFO - Failure caused by syntax error at or near "temperature"
LINE 4:         temperature FLOAT, 
                ^
[2024-11-21T02:09:34.435+0000] {taskinstance.py:1225} INFO - Marking task as UP_FOR_RETRY. dag_id=weather_stock_prediction, task_id=create_prediction_table, run_id=manual__2024-11-21T02:09:25.236263+00:00, execution_date=20241121T020925, start_date=20241121T020933, end_date=20241121T020934
[2024-11-21T02:09:34.454+0000] {taskinstance.py:340} INFO - ::group::Post task execution logs
[2024-11-21T02:09:34.456+0000] {standard_task_runner.py:124} ERROR - Failed to execute job 49 for task create_prediction_table (syntax error at or near "temperature"
LINE 4:         temperature FLOAT, 
                ^
; 1616)
Traceback (most recent call last):
  File "/home/airflow/.local/lib/python3.12/site-packages/airflow/task/task_runner/standard_task_runner.py", line 117, in _start_by_fork
    ret = args.func(args, dag=self.dag)
          ^^^^^^^^^^^^^^^^^^^^^^^^^^^^^
  File "/home/airflow/.local/lib/python3.12/site-packages/airflow/cli/cli_config.py", line 49, in command
    return func(*args, **kwargs)
           ^^^^^^^^^^^^^^^^^^^^^
  File "/home/airflow/.local/lib/python3.12/site-packages/airflow/utils/cli.py", line 116, in wrapper
    return f(*args, **kwargs)
           ^^^^^^^^^^^^^^^^^^
  File "/home/airflow/.local/lib/python3.12/site-packages/airflow/cli/commands/task_command.py", line 483, in task_run
    task_return_code = _run_task_by_selected_method(args, _dag, ti)
                       ^^^^^^^^^^^^^^^^^^^^^^^^^^^^^^^^^^^^^^^^^^^^
  File "/home/airflow/.local/lib/python3.12/site-packages/airflow/cli/commands/task_command.py", line 256, in _run_task_by_selected_method
    return _run_raw_task(args, ti)
           ^^^^^^^^^^^^^^^^^^^^^^^
  File "/home/airflow/.local/lib/python3.12/site-packages/airflow/cli/commands/task_command.py", line 341, in _run_raw_task
    return ti._run_raw_task(
           ^^^^^^^^^^^^^^^^^
  File "/home/airflow/.local/lib/python3.12/site-packages/airflow/utils/session.py", line 97, in wrapper
    return func(*args, session=session, **kwargs)
           ^^^^^^^^^^^^^^^^^^^^^^^^^^^^^^^^^^^^^^
  File "/home/airflow/.local/lib/python3.12/site-packages/airflow/models/taskinstance.py", line 3005, in _run_raw_task
    return _run_raw_task(
           ^^^^^^^^^^^^^^
  File "/home/airflow/.local/lib/python3.12/site-packages/airflow/models/taskinstance.py", line 273, in _run_raw_task
    TaskInstance._execute_task_with_callbacks(
  File "/home/airflow/.local/lib/python3.12/site-packages/airflow/models/taskinstance.py", line 3159, in _execute_task_with_callbacks
    result = self._execute_task(context, task_orig)
             ^^^^^^^^^^^^^^^^^^^^^^^^^^^^^^^^^^^^^^
  File "/home/airflow/.local/lib/python3.12/site-packages/airflow/models/taskinstance.py", line 3183, in _execute_task
    return _execute_task(self, context, task_orig)
           ^^^^^^^^^^^^^^^^^^^^^^^^^^^^^^^^^^^^^^^
  File "/home/airflow/.local/lib/python3.12/site-packages/airflow/models/taskinstance.py", line 767, in _execute_task
    result = _execute_callable(context=context, **execute_callable_kwargs)
             ^^^^^^^^^^^^^^^^^^^^^^^^^^^^^^^^^^^^^^^^^^^^^^^^^^^^^^^^^^^^^
  File "/home/airflow/.local/lib/python3.12/site-packages/airflow/models/taskinstance.py", line 733, in _execute_callable
    return ExecutionCallableRunner(
           ^^^^^^^^^^^^^^^^^^^^^^^^
  File "/home/airflow/.local/lib/python3.12/site-packages/airflow/utils/operator_helpers.py", line 252, in run
    return self.func(*args, **kwargs)
           ^^^^^^^^^^^^^^^^^^^^^^^^^^
  File "/home/airflow/.local/lib/python3.12/site-packages/airflow/models/baseoperator.py", line 417, in wrapper
    return func(self, *args, **kwargs)
           ^^^^^^^^^^^^^^^^^^^^^^^^^^^
  File "/home/airflow/.local/lib/python3.12/site-packages/airflow/providers/common/sql/operators/sql.py", line 284, in execute
    output = hook.run(
             ^^^^^^^^^
  File "/home/airflow/.local/lib/python3.12/site-packages/airflow/providers/common/sql/hooks/sql.py", line 489, in run
    self._run_command(cur, sql_statement, parameters)
  File "/home/airflow/.local/lib/python3.12/site-packages/airflow/providers/common/sql/hooks/sql.py", line 549, in _run_command
    cur.execute(sql_statement)
psycopg2.errors.SyntaxError: syntax error at or near "temperature"
LINE 4:         temperature FLOAT, 
                ^

[2024-11-21T02:09:34.478+0000] {local_task_job_runner.py:266} INFO - Task exited with return code 1
[2024-11-21T02:09:34.521+0000] {taskinstance.py:3895} INFO - 0 downstream tasks scheduled from follow-on schedule check
[2024-11-21T02:09:34.534+0000] {local_task_job_runner.py:245} INFO - ::endgroup::
